<?xml version="1.0" encoding="utf-8"?>
<!-- This URDF was automatically created by SolidWorks to URDF Exporter! Originally created by Stephen Brawner (brawner@gmail.com) 
     Commit Version: 1.6.0-4-g7f85cfe  Build Version: 1.6.7995.38578
     For more information, please see http://wiki.ros.org/sw_urdf_exporter -->
<robot
  name="drone_description">
  <link
    name="base_link">
    <inertial>
      <origin
        xyz="-0.0263 -0.00062804 0.037744"
        rpy="0 0 0" />
      <mass
        value="3.3794" />
      <inertia
        ixx="0.0032142"
        ixy="2.0003E-05"
        ixz="0.00014346"
        iyy="0.0098163"
        iyz="2.3093E-06"
        izz="0.011438" />
    </inertial>
    <visual>
      <origin
        xyz="0 0 0"
        rpy="0 0 0" />
      <geometry>
        <mesh
          filename="package://drone_description/meshes/base_link.STL" />
      </geometry>
      <material
        name="">
        <color
          rgba="0.75294 0.75294 0.75294 1" />
      </material>
    </visual>
    <collision>
      <origin
        xyz="0 0 0"
        rpy="0 0 0" />
      <geometry>
        <mesh
          filename="package://drone_description/meshes/base_link.STL" />
      </geometry>
    </collision>
  </link>
  <link
    name="fr_prop_link">
    <inertial>
      <origin
        xyz="0.00228621059042466 -0.000604146249716386 -0.0318658213695621"
        rpy="0 0 0" />
      <mass
        value="0.0517742689956703" />
      <inertia
        ixx="0.00020810059955811"
        ixy="-0.000184191765063913"
        ixz="-9.16178396754691E-06"
        iyy="0.000185580068186671"
        iyz="-9.44332350493997E-06"
        izz="0.000383998449916041" />
    </inertial>
    <visual>
      <origin
        xyz="0 0 0"
        rpy="0 0 0" />
      <geometry>
        <mesh
          filename="package://drone_description/meshes/fr_prop_link.STL" />
      </geometry>
      <material
        name="">
        <color
          rgba="0.792156862745098 0.819607843137255 0.933333333333333 1" />
      </material>
    </visual>
    <collision>
      <origin
        xyz="0 0 0"
        rpy="0 0 0" />
      <geometry>
        <mesh
          filename="package://drone_description/meshes/fr_prop_link.STL" />
      </geometry>
    </collision>
  </link>
  <joint
    name="fr_prop_joint"
    type="continuous">
    <origin
      xyz="0.28386 -0.36292 -0.024736"
      rpy="0 0 0" />
    <parent
      link="base_link" />
    <child
      link="fr_prop_link" />
    <axis
      xyz="0.071515 -0.018874 -0.99726" />
  </joint>
  <link
    name="fl_prop_link">
    <inertial>
      <origin
        xyz="0.00228581969045111 0.00060169080665684 -0.0318660775251255"
        rpy="0 0 0" />
      <mass
        value="0.0517760704391253" />
      <inertia
        ixx="9.8918195644481E-05"
        ixy="-0.000155099063110766"
        ixz="-2.34158800542053E-05"
        iyy="0.000296242182126736"
        iyz="-1.27924825727884E-05"
        izz="0.00038259207672918" />
    </inertial>
    <visual>
      <origin
        xyz="0 0 0"
        rpy="0 0 0" />
      <geometry>
        <mesh
          filename="package://drone_description/meshes/fl_prop_link.STL" />
      </geometry>
      <material
        name="">
        <color
          rgba="0.792156862745098 0.819607843137255 0.933333333333333 1" />
      </material>
    </visual>
    <collision>
      <origin
        xyz="0 0 0"
        rpy="0 0 0" />
      <geometry>
        <mesh
          filename="package://drone_description/meshes/fl_prop_link.STL" />
      </geometry>
    </collision>
  </link>
  <joint
    name="fl_prop_joint"
    type="continuous">
    <origin
      xyz="0.28386 0.36292 -0.024736"
      rpy="0 0 0" />
    <parent
      link="base_link" />
    <child
      link="fl_prop_link" />
    <axis
      xyz="0.071515 0.018874 -0.99726" />
  </joint>
  <link
    name="br_prop_link">
    <inertial>
      <origin
        xyz="-0.00232088263222802 -0.000444276465700444 -0.0318661799537909"
        rpy="0 0 0" />
      <mass
        value="0.0517759661201676" />
      <inertia
        ixx="9.74094714604786E-05"
        ixy="-0.000154192657922875"
        ixz="2.30593067513961E-05"
        iyy="0.000297682090921109"
        iyz="1.24406886381546E-05"
        izz="0.000382660292259361" />
    </inertial>
    <visual>
      <origin
        xyz="0 0 0"
        rpy="0 0 0" />
      <geometry>
        <mesh
          filename="package://drone_description/meshes/br_prop_link.STL" />
      </geometry>
      <material
        name="">
        <color
          rgba="0.792156862745098 0.819607843137255 0.933333333333333 1" />
      </material>
    </visual>
    <collision>
      <origin
        xyz="0 0 0"
        rpy="0 0 0" />
      <geometry>
        <mesh
          filename="package://drone_description/meshes/br_prop_link.STL" />
      </geometry>
    </collision>
  </link>
  <joint
    name="br_prop_joint"
    type="continuous">
    <origin
      xyz="-0.30489 -0.31528 -0.024736"
      rpy="0 0 0" />
    <parent
      link="base_link" />
    <child
      link="br_prop_link" />
    <axis
      xyz="-0.072653 -0.013861 -0.99726" />
  </joint>
  <link
    name="bl_prop_link">
    <inertial>
      <origin
        xyz="-0.00232102854999633 0.000441469285262786 -0.031866208920347"
        rpy="0 0 0" />
      <mass
        value="0.0517760690289633" />
      <inertia
        ixx="9.70174132751842E-05"
        ixy="-0.000154518358180511"
        ixz="1.87971058580249E-05"
        iyy="0.000297452292085239"
        iyz="1.00474312963819E-05"
        izz="0.000383284621812351" />
    </inertial>
    <visual>
      <origin
        xyz="0 0 0"
        rpy="0 0 0" />
      <geometry>
        <mesh
          filename="package://drone_description/meshes/bl_prop_link.STL" />
      </geometry>
      <material
        name="">
        <color
          rgba="0.792156862745098 0.819607843137255 0.933333333333333 1" />
      </material>
    </visual>
    <collision>
      <origin
        xyz="0 0 0"
        rpy="0 0 0" />
      <geometry>
        <mesh
          filename="package://drone_description/meshes/bl_prop_link.STL" />
      </geometry>
    </collision>
  </link>
  <joint
    name="bl_prop_joint"
    type="continuous">
    <origin
      xyz="-0.30489 0.31529 -0.024736"
      rpy="0 0 0" />
    <parent
      link="base_link" />
    <child
      link="bl_prop_link" />
    <axis
      xyz="-0.072653 0.013861 -0.99726" />
  </joint>
  <link
    name="arm_one_link">
    <inertial>
      <origin
        xyz="-0.0275982252224184 -0.0046307535698818 -0.0438910198457915"
        rpy="0 0 0" />
      <mass
        value="0.0498847677411126" />
      <inertia
        ixx="3.50342194631533E-05"
        ixy="-3.7826275192224E-06"
        ixz="-2.28307688907572E-05"
        iyy="5.69431151096246E-05"
        iyz="-3.83081389081462E-06"
        izz="2.81513689104768E-05" />
    </inertial>
    <visual>
      <origin
        xyz="0 0 0"
        rpy="0 0 0" />
      <geometry>
        <mesh
          filename="package://drone_description/meshes/arm_one_link.STL" />
      </geometry>
      <material
        name="">
        <color
          rgba="0.792156862745098 0.819607843137255 0.933333333333333 1" />
      </material>
    </visual>
    <collision>
      <origin
        xyz="0 0 0"
        rpy="0 0 0" />
      <geometry>
        <mesh
          filename="package://drone_description/meshes/arm_one_link.STL" />
      </geometry>
    </collision>
  </link>
  <joint
    name="arm_one_joint"
    type="continuous">
    <origin
      xyz="0.1262 0 -0.0519"
      rpy="0 0 0" />
    <parent
      link="base_link" />
    <child
      link="arm_one_link" />
    <axis
      xyz="0 0 -1" />
  </joint>
  <link
    name="arm_two_link">
    <inertial>
      <origin
        xyz="0.0357412876512809 -0.00170781054391012 0.000117767265252061"
        rpy="0 0 0" />
      <mass
        value="0.0326792841533979" />
      <inertia
        ixx="3.8181753059861E-05"
        ixy="1.12770263430845E-05"
        ixz="-2.4216171249835E-07"
        iyy="3.01112818927873E-05"
        iyz="5.68241831366402E-07"
        izz="6.53869048673944E-05" />
    </inertial>
    <visual>
      <origin
        xyz="0 0 0"
        rpy="0 0 0" />
      <geometry>
        <mesh
          filename="package://drone_description/meshes/arm_two_link.STL" />
      </geometry>
      <material
        name="">
        <color
          rgba="0.792156862745098 0.819607843137255 0.933333333333333 1" />
      </material>
    </visual>
    <collision>
      <origin
        xyz="0 0 0"
        rpy="0 0 0" />
      <geometry>
        <mesh
          filename="package://drone_description/meshes/arm_two_link.STL" />
      </geometry>
    </collision>
  </link>
  <joint
    name="arm_two_joint"
    type="continuous">
    <origin
      xyz="-0.061989 -0.010401 -0.10386"
      rpy="0 0 0" />
    <parent
      link="arm_one_link" />
    <child
      link="arm_two_link" />
    <axis
      xyz="-0.98621 -0.16548 0" />
  </joint>
  <link
    name="camera_link">
    <inertial>
      <origin
        xyz="-0.00804648665789653 0.0369732181362619 -0.00076184698056192"
        rpy="0 0 0" />
      <mass
        value="0.36349979485356" />
      <inertia
        ixx="0.00022688741131706"
        ixy="-2.16219970412951E-05"
        ixz="1.16359838977465E-07"
        iyy="0.000369363723647684"
        iyz="4.27923991833458E-07"
        izz="0.000396225584343995" />
    </inertial>
    <visual>
      <origin
        xyz="0 0 0"
        rpy="0 0 0" />
      <geometry>
        <mesh
          filename="package://drone_description/meshes/camera_link.STL" />
      </geometry>
      <material
        name="">
        <color
          rgba="0.792156862745098 0.819607843137255 0.933333333333333 1" />
      </material>
    </visual>
    <collision>
      <origin
        xyz="0 0 0"
        rpy="0 0 0" />
      <geometry>
        <mesh
          filename="package://drone_description/meshes/camera_link.STL" />
      </geometry>
    </collision>
  </link>
  <joint
    name="camera_joint"
    type="continuous">
    <origin
      xyz="0.073433 -0.026712 0.00059662"
      rpy="0 0 0" />
    <parent
      link="arm_two_link" />
    <child
      link="camera_link" />
    <axis
      xyz="-0.16546 0.98609 -0.015497" />
  </joint>
</robot>